<?xml version="1.0"?>
<robot name="KR300">
	<link name='link1'>
		<d>0.675</d>
		<a>0.35</a>
		<alpha>-1.5707963267948966</alpha>
		<I>[17.42, 31.75, 34.93, 2.455, -0.1234, -4.47056]</I>
		<r>[-0.35217374, 0.16990937, -0.011424]</r>
		<m>402.26</m>
		<Jm>0.00923</Jm>
		<G>212.76</G>
		<B>0.0021517</B>
		<Tc>[0.89302, -0.89302]</Tc>
		<qlim>[-147, 147]</qlim>
		<offset>-90</offset>
		<flip>True</flip>
	</link>
	<link name='link2'>
		<d>-0.189</d>
		<a>1.15</a>
		<alpha>0</alpha>
		<I>[7.293, 87.42, 87.12, -0.66, -0.09125, 3.924]</I>
		<r>[-0.70534904, -0.00356655, 0.0]</r>
		<m>332.14</m>
		<Jm>0.0118</Jm>
		<G>203.52</G>
		<B>0.0184437</B>
		<Tc>[2.45399, -2.45399]</Tc>
		<qlim>[-140, -5]</qlim>
		<offset>0</offset>
	</link>
	<link name='link3'>
		<d>0.189</d>
		<a>0.041</a>
		<alpha>-1.5707963267948966</alpha>
		<I>[23.17, 23.15, 3.4341, -0.2545, 1.27099, 1.085]</I>
		<r>[-0.0398514, -0.0430814, -0.18383108]</r>
		<m>167.89</m>
		<Jm>0.0118</Jm>
		<G>192.75</G>
		<B>0.0143936</B>
		<Tc>[2.33463, -2.33463]</Tc>
		<qlim>[-112, 153]</qlim>
		<offset>90</offset>
	</link>
	<link name='link4'>
		<d>-1</d>
		<a>0</a>
		<alpha>1.5707963267948966</alpha>
		<I>[0.1324, 0.04509, 0.1361, 5.608e-07, 0.00653, -5.01236e-07]</I>
		<r>[5.5e-07, 0.12191066, 0.00432167]</r>
		<m>9.69</m>
		<Jm>0.00173</Jm>
		<G>156</G>
		<B>0.0038455</B>
		<Tc>[0.60897, -0.60897]</Tc>
		<qlim>[-350, 350]</qlim>
		<offset>0</offset>
	</link>
	<link name='link5'>
		<d>0</d>
		<a>0</a>
		<alpha>-1.5707963267948966</alpha>
		<I>[0.7185, 0.555113, 0.4384, 3.801e-05, 0.1519, 0.0001056]</I>
		<r>[4.54e-06, -0.04996316, -0.05916827]</r>
		<m>49.61</m>
		<Jm>0.00173</Jm>
		<G>156</G>
		<B>0.0038455</B>
		<Tc>[0.60897, -0.60897]</Tc>
		<qlim>[-122.5, 122.5]</qlim>
		<offset>0</offset>
	</link>
	<link name='link6'>
		<d>-0.24</d>
		<a>0</a>
		<alpha>3.141592653589793</alpha>
		<I>[0.0388, 0.1323, 0.1681, 0.02635, 0.00159, -0.003322]</I>
		<r>[-0.06663199, 0.01720624, -0.01663216]</r>
		<m>9.18</m>
		<Jm>0.00173</Jm>
		<G>102.17</G>
		<B>0.0050314</B>
		<Tc>[0.53832, -0.53832]</Tc>
		<qlim>[-350, 350]</qlim>
	</link>
	<joint name='joint1' type='revolute'>
		<parent link='link0'/>
		<child link='link1'/>
		<origin xyz='0 0 0' rpy='0 0 0'/>
		<axis xyz='0 0 1'/>
		<limit lower='-350' upper='350'/>
	</joint>
	<joint name='joint2' type='revolute'>
		<parent link='link1'/>
		<child link='link2'/>
		<origin xyz='0 0 0' rpy='0 0 0'/>
		<axis xyz='0 0 1'/>
		<limit lower='-350' upper='350'/>
	</joint>
	<joint name='joint3' type='revolute'>
		<parent link='link2'/>
		<child link='link3'/>
		<origin xyz='0 0 0' rpy='0 0 0'/>
		<axis xyz='0 0 1'/>
		<limit lower='-350' upper='350'/>
	</joint>
	<joint name='joint4' type='revolute'>
		<parent link='link3'/>
		<child link='link4'/>
		<origin xyz='0 0 0' rpy='0 0 0'/>
		<axis xyz='0 0 1'/>
		<limit lower='-350' upper='350'/>
	</joint>
	<joint name='joint5' type='revolute'>
		<parent link='link4'/>
		<child link='link5'/>
		<origin xyz='0 0 0' rpy='0 0 0'/>
		<axis xyz='0 0 1'/>
		<limit lower='-350' upper='350'/>
	</joint>
	<joint name='joint6' type='revolute'>
		<parent link='link5'/>
		<child link='link6'/>
		<origin xyz='0 0 0' rpy='0 0 0'/>
		<axis xyz='0 0 1'/>
		<limit lower='-350' upper='350'/>
	</joint>
	<group_state name='pose_0'>
		<joint name='joint1' value='0'/>
		<joint name='joint2' value='0'/>
		<joint name='joint3' value='0'/>
		<joint name='joint4' value='0'/>
		<joint name='joint5' value='0'/>
		<joint name='joint6' value='0'/>
	</group_state>
	<group_state name='pose_1'>
		<joint name='joint1' value='0'/>
		<joint name='joint2' value='-1.5707963267948966'/>
		<joint name='joint3' value='1.5707963267948966'/>
		<joint name='joint4' value='0'/>
		<joint name='joint5' value='0'/>
		<joint name='joint6' value='0'/>
	</group_state>
	<group_state name='pose_2'>
		<joint name='joint1' value='0'/>
		<joint name='joint2' value='-2.0943951023931953'/>
		<joint name='joint3' value='2.356194490192345'/>
		<joint name='joint4' value='0'/>
		<joint name='joint5' value='0.7853981633974483'/>
		<joint name='joint6' value='0'/>
	</group_state>
	<group_state name='pose_3'>
		<joint name='joint1' value='0'/>
		<joint name='joint2' value='1.5707963267948966'/>
		<joint name='joint3' value='0'/>
		<joint name='joint4' value='0'/>
		<joint name='joint5' value='0'/>
		<joint name='joint6' value='0'/>
	</group_state>
	<group_state name='pose_4'>
		<joint name='joint1' value='0'/>
		<joint name='joint2' value='-140'/>
		<joint name='joint3' value='150'/>
		<joint name='joint4' value='0'/>
		<joint name='joint5' value='-120'/>
		<joint name='joint6' value='0'/>
	</group_state>
</robot>